<?xml version="1.0"?>
<robot name="mikibot">
  <link name="base">
    <visual>
      <geometry>
        <box size="0.2 0.3 0.1"/>
      </geometry>
    </visual>
    <inertial>
      <mass value="10"/>
      <inertia ixx="0.4" ixy="0.0" ixz="0.0" iyy="0.4" iyz="0.0" izz="0.2"/>
    </inertial>
    <collision>
       <geometry>
        <box size="0.2 0.3 0.1"/>
      </geometry>
    </collision> 
  </link>
 <link name="body">
    <visual>
      <geometry>
        <cylinder length="0.1" radius="0.2"/>
      </geometry>
      <origin rpy="0 0 1.57075" xyz="0 0 0.05"/>
    </visual>
    <inertial>
      <mass value="10"/>
      <inertia ixx="0.4" ixy="0.0" ixz="0.0" iyy="0.4" iyz="0.0" izz="0.2"/>
    </inertial>
    <collision>
       <geometry>
        <cylinder length="0.1" radius="0.2"/>
      </geometry>
    </collision> 
  </link>
<joint name="base_to_body" type="fixed">
    <parent link="base"/>
    <child link="body"/>
    <origin xyz="0 0 0"/>
  </joint>

  <link name="fbump">
    <visual>
      <geometry>
        <box size="0.2 0.2 0.02"/>
      </geometry>
      <origin rpy="0 0 0" xyz="0.1 0 0.07"/>
    </visual>
    <inertial>
      <mass value="10"/>
      <inertia ixx="0.4" ixy="0.0" ixz="0.0" iyy="0.4" iyz="0.0" izz="0.2"/>
    </inertial>
    <collision>
       <geometry>
        <box size="0.2 0.2 0.02"/>
      </geometry>
    </collision> 
  </link>
<joint name="bumpbod" type="fixed">
    <parent link="base"/>
    <child link="fbump"/>
    <origin xyz="0 0 0"/>
  </joint>
<link name="bl_wheel">
    <visual>
      <geometry>
        <cylinder length="0.05" radius="0.04"/>
      </geometry>
      <material name="black">
        <color rgba="0 0 0 1"/>
      </material>
    </visual>
    <inertial>
      <mass value="10"/>
      <inertia ixx="0.4" ixy="0.0" ixz="0.0" iyy="0.4" iyz="0.0" izz="0.2"/>
    </inertial>
     <collision>
       <geometry>
        <cylinder length="0.05" radius="0.04"/>
      </geometry>
     </collision>  
</link>

<joint name="lwd_joint" type="continuous">
    <axis xyz="0 0 1"/>
    <parent link="base"/>
    <child link="bl_wheel"/>
    <origin rpy="1.57075 0 3.14" xyz="-0.1 0.1 -0.05"/>
    <limit effort="100" velocity="100"/>
    <dynamics damping="1.0" friction="1.0"/>
  </joint>

<link name="br_wheel">
    <visual>
      <geometry>
        <cylinder length="0.05" radius="0.04"/>
      </geometry>
      <material name="black">
        <color rgba="0 0 0 1"/>
      </material>
    </visual>
    <inertial>
      <mass value="10"/>
      <inertia ixx="0.4" ixy="0.0" ixz="0.0" iyy="0.4" iyz="0.0" izz="0.2"/>
    </inertial>
     <collision>
       <geometry>
        <cylinder length="0.05" radius="0.04"/>
      </geometry>
     </collision>  
</link>
<joint name="rwd_joint" type="continuous">
    <axis xyz="0 0 1"/>
    <parent link="base"/>
    <child link="br_wheel"/>
    <origin rpy="1.57075 0 3.14" xyz="-0.1 -0.1 -0.05"/>
    <limit effort="100" velocity="100"/>
    <dynamics damping="1.0" friction="1.0"/>
  </joint>


<link name="roller">
    <visual>
      <geometry>
        <sphere length="0.1" radius="0.06"/>
      </geometry>
      <origin rpy="0 0 0" xyz="0 0 0"/>
      <material name="black">
        <color rgba="0 0 0 1"/>
      </material>
    </visual>
    <inertial>
      <mass value="10"/>
      <inertia ixx="0.4" ixy="0.0" ixz="0.0" iyy="0.4" iyz="0.0" izz="0.2"/>
    </inertial>
      <collision>
       <geometry>
        <sphere length="0.1" radius="0.06"/>
       </geometry>
       <surface>
        <friction>
          <ode>
            <mu>0</mu>
            <mu2>0</mu2>
            <slip1>1.0</slip1>
            <slip2>1.0</slip2>
          </ode>
        </friction>
      </surface>
      </collision>
</link>
<joint name="rollercast" type="continuous">
    <parent link="base"/>
    <child link="roller"/>
    <origin rpy="0 0 0" xyz="0.1 0 -0.025"/>
    <limit effort="100" velocity="100"/>
    <dynamics damping="0.0" friction="0.0"/>
  </joint>
 <link name="leftman">
    <visual>
      <geometry>
        <cylinder length="0.1" radius="0.03"/>
      </geometry>
      <origin rpy="0 0 0" xyz="0.1 0.1 0.1"/>
    </visual>
    <inertial>
      <mass value="10"/>
      <inertia ixx="0.4" ixy="0.0" ixz="0.0" iyy="0.4" iyz="0.0" izz="0.2"/>
    </inertial>
     <collision>
       <geometry>
        <sphere length="0.1" radius="0.03"/>
       </geometry>
     </collision>
 </link>
  <joint name="Left_mandible" type="fixed">
    <axis xyz="0 0 -1"/>
    <limit effort="1000.0" lower="0.0" upper="0.548" velocity="0.5"/>
    <origin rpy="0 0 0" xyz="0 0 0"/>
    <parent link="base"/>
    <child link="leftman"/>
 </joint>
 <link name="lefthand">
    <visual>
      <geometry>
        <box size='0.3 0.02 0.05'/>
      </geometry>
      <origin rpy="0 0 45" xyz="0.15 0.15 0.1"/>
    </visual>
    <inertial>
      <mass value="10"/>
      <inertia ixx="0.4" ixy="0.0" ixz="0.0" iyy="0.4" iyz="0.0" izz="0.2"/>
    </inertial>
      <collision>
       <geometry>
        <box size='0.4 0.02 0.05'/>
       </geometry>
      </collision>
  </link>

 <link name="rightman">
    <visual>
      <geometry>
        <cylinder length="0.1" radius="0.03"/>
      </geometry>
      <origin rpy="0 0 0" xyz="0.1 -0.1 0.1"/>
    </visual>
    <inertial>
      <mass value="10"/>
      <inertia ixx="0.4" ixy="0.0" ixz="0.0" iyy="0.4" iyz="0.0" izz="0.2"/>
    </inertial>
      <collision>
       <geometry>
        <cylinder length="0.1" radius="0.03"/>
       </geometry>
      </collision> 
  </link>
  <joint name="Right_mandible" type="fixed">
    <axis xyz="0 0 1"/>
    <limit effort="1000.0" lower="0.0" upper="0.548" velocity="0.5"/>
    <origin rpy="0 0 0" xyz="0 0 0"/>
    <parent link="base"/>
    <child link="rightman"/>
  </joint>
 <link name="righthand">
    <visual>
      <geometry>
        <box size='0.3 0.02 0.05'/>
      </geometry>
      <origin rpy="0 0 -45" xyz="0.15 -0.15 0.1"/>
    </visual>
    <inertial>
      <mass value="10"/>
      <inertia ixx="0.4" ixy="0.0" ixz="0.0" iyy="0.4" iyz="0.0" izz="0.2"/>
    </inertial>
      <collision>
       <geometry>
        <box size='0.4 0.02 0.05'/>
       </geometry>
      </collision>
  </link>

<joint name="gripper_left" type="revolute">
	<axis xyz="0 0 1"/>
    <limit effort="1000.0" lower="0.0" upper="-0.548" velocity="0.5"/>
    <origin rpy="0 0 0" xyz="0 0 0"/>
    <parent link="base"/>
    <child link="lefthand"/>
    <origin xyz="0 0 0"/>
  </joint>
<joint name="gripper_right" type="revolute">
	<axis xyz="0 0 1"/>
    <limit effort="1000.0" lower="0.0" upper="0.548" velocity="0.5"/>
    <origin rpy="0 0 0" xyz="0 0 0"/>
    <parent link="base"/>
    <child link="righthand"/>
    <origin xyz="0 0 0"/>
  </joint>
 

  <transmission name="tran1">
    <type>transmission_interface/SimpleTransmission</type>
    <joint name="gripper_left">
      <hardwareInterface>EffortJointInterface</hardwareInterface>
    </joint>
    <actuator name="motor1">
      <hardwareInterface>EffortJointInterface</hardwareInterface>
      <mechanicalReduction>1</mechanicalReduction>
    </actuator>
  </transmission>

  <transmission name="tran2">
    <type>transmission_interface/SimpleTransmission</type>
    <joint name="gripper_right">
      <hardwareInterface>EffortJointInterface</hardwareInterface>
    </joint>
    <actuator name="motor2">
      <hardwareInterface>EffortJointInterface</hardwareInterface>
      <mechanicalReduction>1</mechanicalReduction>
    </actuator>
  </transmission>






<gazebo>  
  <plugin name="differential_drive_controller" filename="libgazebo_ros_diff_drive.so">
    <!-- Plugin update rate in Hz -->
    <updateRate>40</updateRate>

    <!-- Name of left joint, defaults to `left_joint` -->
    <leftJoint>lwd_joint</leftJoint>

    <!-- Name of right joint, defaults to `right_joint` -->
    <rightJoint>rwd_joint</rightJoint>

    <!-- The distance from the center of one wheel to the other, in meters, defaults to 0.34 m -->
    <wheelSeparation>0.3</wheelSeparation>

    <!-- Diameter of the wheels, in meters, defaults to 0.15 m -->
    <wheelDiameter>0.2</wheelDiameter>

    <!-- Wheel acceleration, in rad/s^2, defaults to 0.0 rad/s^2 -->
    <wheelAcceleration>1.0</wheelAcceleration>

    <!-- Maximum torque which the wheels can produce, in Nm, defaults to 5 Nm -->
    <wheelTorque>20</wheelTorque>

    <!-- Topic to receive geometry_msgs/Twist message commands, defaults to `cmd_vel` -->
    <commandTopic>cmd_vel</commandTopic>

    <!-- Topic to publish nav_msgs/Odometry messages, defaults to `odom` -->
    <odometryTopic>odom</odometryTopic>

    <!-- Odometry frame, defaults to `odom` -->
    <odometryFrame>odom</odometryFrame>

    <!-- Robot frame to calculate odometry from, defaults to `base_footprint` -->
    <robotBaseFrame>base</robotBaseFrame>

    <!-- Odometry source, 0 for ENCODER, 1 for WORLD, defaults to WORLD -->
    <odometrySource>1</odometrySource>

    <!-- Set to true to publish transforms for the wheel links, defaults to false -->
    <publishWheelTF>true</publishWheelTF>

    <!-- Set to true to publish transforms for the odometry, defaults to true -->
    <publishOdom>true</publishOdom>

    <!-- Set to true to publish sensor_msgs/JointState on /joint_states for the wheel joints, defaults to false -->
    <publishWheelJointState>true</publishWheelJointState>

    <!-- Set to true to swap right and left wheels, defaults to true -->
    <legacyMode>false</legacyMode>
  </plugin>
</gazebo>

<gazebo refrence="fbump">
	<sensor type="contact" name="fbumpcont">
  <plugin name="fbump_gazebo_ros_bumper_controller" filename="libgazebo_ros_bumper.so">
    <alwaysOn>true</alwaysOn>
    <updateRate>40</updateRate>
    <bumperTopicName>fbump_bumper</bumperTopicName>
    <frameName>bumper</frameName>
  </plugin>
</sensor>
</gazebo>

</robot>
